<?xml version="1.0"?>
<robot xmlns:xacro="http://www.ros.org/wiki/xacro">

    <!-- Include inertial macros file -->
    <xacro:include filename="inertial_macros.xacro"/>

    <!-- Define colors -->
    <material name="white">
        <color rgba="1 1 1 1"/>
    </material>
    
    <material name="orange">
        <color rgba="1 0.3 0.1 1"/>
    </material>
    
    <material name="blue">
        <color rgba="0.2 0.2 1 1"/>
    </material>
    
    <material name="black">
        <color rgba="0 0 0 1"/>
    </material>
    
    <material name="red">
        <color rgba="1 0 0 1"/>
    </material>
    
    <material name="green">
        <color rgba="0 1 0 1"/>
    </material>

    <material name="wheel_color">
        <color rgba="0.1 0.1 0.1 1"/> <!-- Dark grey -->
    </material>

    <material name="chassis_color">
        <color rgba="0.8 0.4 0.1 1.0"/>  <!-- Darker orange -->
    </material>

    <!-- Initialize the base link -->
    <link name="base_link">

    </link>

    <!-- Base footprint joint and link -->
    <joint name="base_footprint_joint" type="fixed">
        <parent link="base_link"/>
        <child link="base_footprint"/>
        <origin xyz="0 0 0" rpy="0 0 0"/>
    </joint>

    <link name="base_footprint"></link>

    <!-- Chassis joint -->
    <joint name="chassis_joint" type="fixed">
        <parent link="base_link"/>
        <child link="chassis"/>
        <origin xyz="-0.1 0 0"/> <!-- Origin behind the base link (back bottom center)-->
    </joint>

    <!-- Chassis link -->
    <link name="chassis">
        <visual>
            <!-- Visual box origin is 0.15m forward and 0.075m up -->
            <origin xyz="0.15 0 0.075"/>  
            <geometry>
                <box size="0.3 0.3 0.15"/> <!-- Size of the robot in meters -->
            </geometry>
            <material name="chassis_color"/>

        </visual>

        <collision>
            <!-- Visual box origin is 0.15m forward and 0.075m up -->
            <origin xyz="0.15 0 0.075"/>  
            <geometry>
                <box size="0.3 0.3 0.15"/> <!-- Size of the robot in meters -->
            </geometry>
        </collision>

        <!-- Inertial box for chassis -->
        <xacro:inertial_box mass="0.3" x="0.3" y="0.3" z="0.15">
            <!-- Same as visual origin -->
            <origin xyz="0.15 0 0.075" rpy="0 0 0"/>
        </xacro:inertial_box>
    </link>
    <!-- Assign color in Gazebo -->
    <gazebo reference="chassis"> 
        <visual>
            <material>
                <ambient>0.5 0.2 0.05 1.0</ambient>
                <diffuse>0.7 0.3 0.1 1.0</diffuse>
                <specular>0.8 0.8 0.8 1.0</specular>
                <emissive>0.0 0.0 0.0 0.0</emissive>
            </material>
        </visual>
    </gazebo>


    <!-- Left wheel joint -->

    <joint name="left_wheel_joint" type="continuous">
        <parent link="base_link"/>
        <child link="left_wheel"/>
        <origin xyz="0 0.175 0" rpy="-${pi/2} 0 0"/>
        <axis xyz="0 0 1"/>
    </joint>

    <!-- Left wheel link -->

    <link name="left_wheel">
        <visual>
            <geometry>
                <cylinder radius="0.05" length="0.04"/>
            </geometry>
            <material name="wheel_color"/>
        </visual>

        <collision>
            <geometry>
                <sphere radius="0.05"/>
            </geometry>
        </collision>
        <!-- Inertial cylinder for wheels -->
        <xacro:inertial_cylinder mass="0.1" radius="0.05" length="0.04">
            <origin xyz="0 0 0" rpy="0 0 0"/>
        </xacro:inertial_cylinder>
    </link>
    <!-- Assign color in Gazebo -->
    <gazebo reference="left_wheel"> 
        <material>Gazebo/FlatBlack</material>
    </gazebo>
    
    <!-- Right wheel joint -->

    <joint name="right_wheel_joint" type="continuous">
        <parent link="base_link"/>
        <child link="right_wheel"/>
        <origin xyz="0 -0.175 0" rpy="${pi/2} 0 0"/>
        <axis xyz="0 0 -1"/>
    </joint>

    <!-- Right wheel link -->

    <link name="right_wheel">
        <visual>
            <geometry>
                <cylinder radius="0.05" length="0.04"/>
            </geometry>
            <material name="wheel_color"/>
        </visual>

        <collision>
            <geometry>
                <sphere radius="0.05"/>
            </geometry>
        </collision>

        <xacro:inertial_cylinder mass="0.1" radius="0.05" length="0.04">
            <origin xyz="0 0 0" rpy="0 0 0"/>
        </xacro:inertial_cylinder>
    </link>
    <!-- Assign color in Gazebo -->
    <gazebo reference="right_wheel"> 
        <material>Gazebo/FlatBlack</material>
    </gazebo>

    <!-- Caster wheel joint -->

    <joint name="caster_wheel_joint" type="fixed">
        <parent link="chassis"/>
        <child link="caster_wheel"/>
        <origin xyz="0.24 0 0"/>
    </joint>

    <!-- Caster wheel link -->

    <link name="caster_wheel">
        <visual>
            <geometry>
                <sphere radius="0.05"/>
            </geometry>
            <material name="wheel_color"/>
        </visual>
        <collision>
            <geometry>
                <sphere radius="0.05"/>
            </geometry>
        </collision>
        <xacro:inertial_sphere mass="0.1" radius="0.05">
            <origin xyz="0 0 0" rpy="0 0 0"/>
        </xacro:inertial_sphere>
    </link>
    <gazebo reference="caster_wheel">
        <material>Gazebo/DarkGrey</material>
        <mu1>0.001</mu1>
        <mu2>0.001</mu2>
    </gazebo>

</robot>